<?xml version="1.0" ?>
<robot name="partnet_544bb6c9c8ff5ebd6c63a10c02702cfc">
	<link name="base"/>
	<link name="link_0">
		<visual name="cover_lid-15">
			<origin xyz="-0.548650619932205 -0.7891369489181312 -0.021128000000000036"/>
			<geometry>
				<mesh filename="package://objects_description/trashcan/textured_objs/original-28.obj"/>
			</geometry>
		</visual>
		<visual name="cover_lid-15">
			<origin xyz="-0.548650619932205 -0.7891369489181312 -0.021128000000000036"/>
			<geometry>
				<mesh filename="package://objects_description/trashcan/textured_objs/original-26.obj"/>
			</geometry>
		</visual>
		<visual name="cover_lid-15">
			<origin xyz="-0.548650619932205 -0.7891369489181312 -0.021128000000000036"/>
			<geometry>
				<mesh filename="package://objects_description/trashcan/textured_objs/original-29.obj"/>
			</geometry>
		</visual>
		<visual name="cover_lid-15">
			<origin xyz="-0.548650619932205 -0.7891369489181312 -0.021128000000000036"/>
			<geometry>
				<mesh filename="package://objects_description/trashcan/textured_objs/original-3.obj"/>
			</geometry>
		</visual>
		<visual name="cover_lid-15">
			<origin xyz="-0.548650619932205 -0.7891369489181312 -0.021128000000000036"/>
			<geometry>
				<mesh filename="package://objects_description/trashcan/textured_objs/original-4.obj"/>
			</geometry>
		</visual>
		<visual name="cover_lid-15">
			<origin xyz="-0.548650619932205 -0.7891369489181312 -0.021128000000000036"/>
			<geometry>
				<mesh filename="package://objects_description/trashcan/textured_objs/original-25.obj"/>
			</geometry>
		</visual>
		<collision>
			<origin xyz="-0.548650619932205 -0.7891369489181312 -0.021128000000000036"/>
			<geometry>
				<mesh filename="package://objects_description/trashcan/textured_objs/original-28.obj"/>
			</geometry>
		</collision>
		<collision>
			<origin xyz="-0.548650619932205 -0.7891369489181312 -0.021128000000000036"/>
			<geometry>
				<mesh filename="package://objects_description/trashcan/textured_objs/original-26.obj"/>
			</geometry>
		</collision>
		<collision>
			<origin xyz="-0.548650619932205 -0.7891369489181312 -0.021128000000000036"/>
			<geometry>
				<mesh filename="package://objects_description/trashcan/textured_objs/original-29.obj"/>
			</geometry>
		</collision>
		<collision>
			<origin xyz="-0.548650619932205 -0.7891369489181312 -0.021128000000000036"/>
			<geometry>
				<mesh filename="package://objects_description/trashcan/textured_objs/original-3.obj"/>
			</geometry>
		</collision>
		<collision>
			<origin xyz="-0.548650619932205 -0.7891369489181312 -0.021128000000000036"/>
			<geometry>
				<mesh filename="package://objects_description/trashcan/textured_objs/original-4.obj"/>
			</geometry>
		</collision>
		<collision>
			<origin xyz="-0.548650619932205 -0.7891369489181312 -0.021128000000000036"/>
			<geometry>
				<mesh filename="package://objects_description/trashcan/textured_objs/original-25.obj"/>
			</geometry>
		</collision>
	</link>
	<joint name="joint_0" type="revolute">
		<origin xyz="0.548650619932205 0.7891369489181312 0.021128000000000036"/>
		<axis xyz="0 0 -1"/>
		<child link="link_0"/>
		<parent link="link_2"/>
		<limit lower="-0.0" upper="1.5707963267948966"/>
	</joint>
	<link name="link_1">
		<visual name="container_foot_tap-11">
			<origin xyz="0.3783070268847557 0.8156094772655749 -0.17812699999999992"/>
			<geometry>
				<mesh filename="package://objects_description/trashcan/textured_objs/original-5.obj"/>
			</geometry>
		</visual>
		<collision>
			<origin xyz="0.3783070268847557 0.8156094772655749 -0.17812699999999992"/>
			<geometry>
				<mesh filename="package://objects_description/trashcan/textured_objs/original-5.obj"/>
			</geometry>
		</collision>
	</link>
	<joint name="joint_1" type="revolute">
		<origin xyz="-0.3783070268847557 -0.8156094772655749 0.17812699999999992"/>
		<axis xyz="0 0 1"/>
		<child link="link_1"/>
		<parent link="link_2"/>
		<limit lower="0.0" upper="0.4398229715025711"/>
	</joint>
	<link name="link_2">
		<visual name="frame_holistic-6">
			<origin xyz="0 0 0"/>
			<geometry>
				<mesh filename="package://objects_description/trashcan/textured_objs/original-27.obj"/>
			</geometry>
		</visual>
		<visual name="frame_bottom-7">
			<origin xyz="0 0 0"/>
			<geometry>
				<mesh filename="package://objects_description/trashcan/textured_objs/original-7.obj"/>
			</geometry>
		</visual>
		<visual name="frame_bottom-7">
			<origin xyz="0 0 0"/>
			<geometry>
				<mesh filename="package://objects_description/trashcan/textured_objs/original-6.obj"/>
			</geometry>
		</visual>
		<visual name="frame_bottom-7">
			<origin xyz="0 0 0"/>
			<geometry>
				<mesh filename="package://objects_description/trashcan/textured_objs/original-24.obj"/>
			</geometry>
		</visual>
		<visual name="frame_bottom-7">
			<origin xyz="0 0 0"/>
			<geometry>
				<mesh filename="package://objects_description/trashcan/textured_objs/original-15.obj"/>
			</geometry>
		</visual>
		<visual name="frame_bottom-7">
			<origin xyz="0 0 0"/>
			<geometry>
				<mesh filename="package://objects_description/trashcan/textured_objs/original-17.obj"/>
			</geometry>
		</visual>
		<visual name="frame_bottom-7">
			<origin xyz="0 0 0"/>
			<geometry>
				<mesh filename="package://objects_description/trashcan/textured_objs/original-23.obj"/>
			</geometry>
		</visual>
		<visual name="frame_bottom-7">
			<origin xyz="0 0 0"/>
			<geometry>
				<mesh filename="package://objects_description/trashcan/textured_objs/original-18.obj"/>
			</geometry>
		</visual>
		<visual name="frame_bottom-7">
			<origin xyz="0 0 0"/>
			<geometry>
				<mesh filename="package://objects_description/trashcan/textured_objs/original-12.obj"/>
			</geometry>
		</visual>
		<visual name="frame_bottom-7">
			<origin xyz="0 0 0"/>
			<geometry>
				<mesh filename="package://objects_description/trashcan/textured_objs/original-13.obj"/>
			</geometry>
		</visual>
		<visual name="frame_bottom-7">
			<origin xyz="0 0 0"/>
			<geometry>
				<mesh filename="package://objects_description/trashcan/textured_objs/original-21.obj"/>
			</geometry>
		</visual>
		<visual name="frame_bottom-7">
			<origin xyz="0 0 0"/>
			<geometry>
				<mesh filename="package://objects_description/trashcan/textured_objs/original-22.obj"/>
			</geometry>
		</visual>
		<visual name="frame_bottom-7">
			<origin xyz="0 0 0"/>
			<geometry>
				<mesh filename="package://objects_description/trashcan/textured_objs/original-14.obj"/>
			</geometry>
		</visual>
		<visual name="frame_bottom-7">
			<origin xyz="0 0 0"/>
			<geometry>
				<mesh filename="package://objects_description/trashcan/textured_objs/original-19.obj"/>
			</geometry>
		</visual>
		<visual name="frame_bottom-7">
			<origin xyz="0 0 0"/>
			<geometry>
				<mesh filename="package://objects_description/trashcan/textured_objs/original-16.obj"/>
			</geometry>
		</visual>
		<visual name="frame_bottom-7">
			<origin xyz="0 0 0"/>
			<geometry>
				<mesh filename="package://objects_description/trashcan/textured_objs/original-20.obj"/>
			</geometry>
		</visual>
		<visual name="other_leaf-17">
			<origin xyz="0 0 0"/>
			<geometry>
				<mesh filename="package://objects_description/trashcan/textured_objs/original-2.obj"/>
			</geometry>
		</visual>
		<visual name="other_leaf-17">
			<origin xyz="0 0 0"/>
			<geometry>
				<mesh filename="package://objects_description/trashcan/textured_objs/original-1.obj"/>
			</geometry>
		</visual>
		<visual name="container_box-10">
			<origin xyz="0 0 0"/>
			<geometry>
				<mesh filename="package://objects_description/trashcan/textured_objs/original-8.obj"/>
			</geometry>
		</visual>
		<visual name="container_bottom-12">
			<origin xyz="0 0 0"/>
			<geometry>
				<mesh filename="package://objects_description/trashcan/textured_objs/original-9.obj"/>
			</geometry>
		</visual>
		<visual name="container_bottom-12">
			<origin xyz="0 0 0"/>
			<geometry>
				<mesh filename="package://objects_description/trashcan/textured_objs/original-10.obj"/>
			</geometry>
		</visual>
		<visual name="container_bottom-12">
			<origin xyz="0 0 0"/>
			<geometry>
				<mesh filename="package://objects_description/trashcan/textured_objs/original-31.obj"/>
			</geometry>
		</visual>
		<visual name="container_bottom-12">
			<origin xyz="0 0 0"/>
			<geometry>
				<mesh filename="package://objects_description/trashcan/textured_objs/original-11.obj"/>
			</geometry>
		</visual>
		<visual name="container_bottom-12">
			<origin xyz="0 0 0"/>
			<geometry>
				<mesh filename="package://objects_description/trashcan/textured_objs/original-30.obj"/>
			</geometry>
		</visual>
		<collision>
			<origin xyz="0 0 0"/>
			<geometry>
				<mesh filename="package://objects_description/trashcan/textured_objs/original-27.obj"/>
			</geometry>
		</collision>
		<collision>
			<origin xyz="0 0 0"/>
			<geometry>
				<mesh filename="package://objects_description/trashcan/textured_objs/original-7.obj"/>
			</geometry>
		</collision>
		<collision>
			<origin xyz="0 0 0"/>
			<geometry>
				<mesh filename="package://objects_description/trashcan/textured_objs/original-6.obj"/>
			</geometry>
		</collision>
		<collision>
			<origin xyz="0 0 0"/>
			<geometry>
				<mesh filename="package://objects_description/trashcan/textured_objs/original-24.obj"/>
			</geometry>
		</collision>
		<collision>
			<origin xyz="0 0 0"/>
			<geometry>
				<mesh filename="package://objects_description/trashcan/textured_objs/original-15.obj"/>
			</geometry>
		</collision>
		<collision>
			<origin xyz="0 0 0"/>
			<geometry>
				<mesh filename="package://objects_description/trashcan/textured_objs/original-17.obj"/>
			</geometry>
		</collision>
		<collision>
			<origin xyz="0 0 0"/>
			<geometry>
				<mesh filename="package://objects_description/trashcan/textured_objs/original-23.obj"/>
			</geometry>
		</collision>
		<collision>
			<origin xyz="0 0 0"/>
			<geometry>
				<mesh filename="package://objects_description/trashcan/textured_objs/original-18.obj"/>
			</geometry>
		</collision>
		<collision>
			<origin xyz="0 0 0"/>
			<geometry>
				<mesh filename="package://objects_description/trashcan/textured_objs/original-12.obj"/>
			</geometry>
		</collision>
		<collision>
			<origin xyz="0 0 0"/>
			<geometry>
				<mesh filename="package://objects_description/trashcan/textured_objs/original-13.obj"/>
			</geometry>
		</collision>
		<collision>
			<origin xyz="0 0 0"/>
			<geometry>
				<mesh filename="package://objects_description/trashcan/textured_objs/original-21.obj"/>
			</geometry>
		</collision>
		<collision>
			<origin xyz="0 0 0"/>
			<geometry>
				<mesh filename="package://objects_description/trashcan/textured_objs/original-22.obj"/>
			</geometry>
		</collision>
		<collision>
			<origin xyz="0 0 0"/>
			<geometry>
				<mesh filename="package://objects_description/trashcan/textured_objs/original-14.obj"/>
			</geometry>
		</collision>
		<collision>
			<origin xyz="0 0 0"/>
			<geometry>
				<mesh filename="package://objects_description/trashcan/textured_objs/original-19.obj"/>
			</geometry>
		</collision>
		<collision>
			<origin xyz="0 0 0"/>
			<geometry>
				<mesh filename="package://objects_description/trashcan/textured_objs/original-16.obj"/>
			</geometry>
		</collision>
		<collision>
			<origin xyz="0 0 0"/>
			<geometry>
				<mesh filename="package://objects_description/trashcan/textured_objs/original-20.obj"/>
			</geometry>
		</collision>
		<collision>
			<origin xyz="0 0 0"/>
			<geometry>
				<mesh filename="package://objects_description/trashcan/textured_objs/original-2.obj"/>
			</geometry>
		</collision>
		<collision>
			<origin xyz="0 0 0"/>
			<geometry>
				<mesh filename="package://objects_description/trashcan/textured_objs/original-1.obj"/>
			</geometry>
		</collision>
		<collision>
			<origin xyz="0 0 0"/>
			<geometry>
				<mesh filename="package://objects_description/trashcan/textured_objs/original-8.obj"/>
			</geometry>
		</collision>
		<collision>
			<origin xyz="0 0 0"/>
			<geometry>
				<mesh filename="package://objects_description/trashcan/textured_objs/original-9.obj"/>
			</geometry>
		</collision>
		<collision>
			<origin xyz="0 0 0"/>
			<geometry>
				<mesh filename="package://objects_description/trashcan/textured_objs/original-10.obj"/>
			</geometry>
		</collision>
		<collision>
			<origin xyz="0 0 0"/>
			<geometry>
				<mesh filename="package://objects_description/trashcan/textured_objs/original-31.obj"/>
			</geometry>
		</collision>
		<collision>
			<origin xyz="0 0 0"/>
			<geometry>
				<mesh filename="package://objects_description/trashcan/textured_objs/original-11.obj"/>
			</geometry>
		</collision>
		<collision>
			<origin xyz="0 0 0"/>
			<geometry>
				<mesh filename="package://objects_description/trashcan/textured_objs/original-30.obj"/>
			</geometry>
		</collision>
	</link>
	<joint name="joint_2" type="fixed">
		<origin rpy="1.570796326794897 0 -1.570796326794897" xyz="0 0 0"/>
		<child link="link_2"/>
		<parent link="base"/>
	</joint>
</robot>
