<?xml version="1.0" ?>
<robot name="partnet_8b886bb1aba6938aa3c97bdad98f8ca">
	<link name="base"/>
	<link name="link_0">
		<visual name="frame-1">
			<origin xyz="0 0 0"/>
			<geometry>
				<mesh filename="package://objects_description/keyboard/textured_objs/original-6.obj"/>
			</geometry>
		</visual>
		<visual name="frame-1">
			<origin xyz="0 0 0"/>
			<geometry>
				<mesh filename="package://objects_description/keyboard/textured_objs/original-80.obj"/>
			</geometry>
		</visual>
		<collision>
			<origin xyz="0 0 0"/>
			<geometry>
				<mesh filename="package://objects_description/keyboard/textured_objs/original-6.obj"/>
			</geometry>
		</collision>
		<collision>
			<origin xyz="0 0 0"/>
			<geometry>
				<mesh filename="package://objects_description/keyboard/textured_objs/original-80.obj"/>
			</geometry>
		</collision>
	</link>
	<joint name="joint_0" type="fixed">
		<origin rpy="1.570796326794897 0 -1.570796326794897" xyz="0 0 0"/>
		<child link="link_0"/>
		<parent link="base"/>
	</joint>
	<link name="link_1">
		<visual name="key-2">
			<origin xyz="0.2305384505420256 -0.04784422458054394 0.11968905767549498"/>
			<geometry>
				<mesh filename="package://objects_description/keyboard/textured_objs/original-20.obj"/>
			</geometry>
		</visual>
		<collision>
			<origin xyz="0.2305384505420256 -0.04784422458054394 0.11968905767549498"/>
			<geometry>
				<mesh filename="package://objects_description/keyboard/textured_objs/original-20.obj"/>
			</geometry>
		</collision>
	</link>
	<joint name="joint_1" type="prismatic">
		<origin xyz="-0.2305384505420256 0.04784422458054394 -0.11968905767549498"/>
		<axis xyz="0 -0.9938588581379322 -0.11065518560268853"/>
		<child link="link_1"/>
		<parent link="link_0"/>
		<limit lower="0" upper="0.01"/>
	</joint>
	<link name="link_2">
		<visual name="key-3">
			<origin xyz="0.2305384505420256 -0.04784422458054394 0.11968905767549498"/>
			<geometry>
				<mesh filename="package://objects_description/keyboard/textured_objs/original-72.obj"/>
			</geometry>
		</visual>
		<collision>
			<origin xyz="0.2305384505420256 -0.04784422458054394 0.11968905767549498"/>
			<geometry>
				<mesh filename="package://objects_description/keyboard/textured_objs/original-72.obj"/>
			</geometry>
		</collision>
	</link>
	<joint name="joint_2" type="prismatic">
		<origin xyz="-0.2305384505420256 0.04784422458054394 -0.11968905767549498"/>
		<axis xyz="0 -0.9938588581379322 -0.11065518560268853"/>
		<child link="link_2"/>
		<parent link="link_0"/>
		<limit lower="0" upper="0.01"/>
	</joint>
	<link name="link_3">
		<visual name="key-4">
			<origin xyz="0.2305384505420256 -0.04784422458054394 0.11968905767549498"/>
			<geometry>
				<mesh filename="package://objects_description/keyboard/textured_objs/original-14.obj"/>
			</geometry>
		</visual>
		<collision>
			<origin xyz="0.2305384505420256 -0.04784422458054394 0.11968905767549498"/>
			<geometry>
				<mesh filename="package://objects_description/keyboard/textured_objs/original-14.obj"/>
			</geometry>
		</collision>
	</link>
	<joint name="joint_3" type="prismatic">
		<origin xyz="-0.2305384505420256 0.04784422458054394 -0.11968905767549498"/>
		<axis xyz="0 -0.9938588581379322 -0.11065518560268853"/>
		<child link="link_3"/>
		<parent link="link_0"/>
		<limit lower="0" upper="0.01"/>
	</joint>
	<link name="link_4">
		<visual name="key-5">
			<origin xyz="0.2305384505420256 -0.04784422458054394 0.11968905767549498"/>
			<geometry>
				<mesh filename="package://objects_description/keyboard/textured_objs/original-10.obj"/>
			</geometry>
		</visual>
		<collision>
			<origin xyz="0.2305384505420256 -0.04784422458054394 0.11968905767549498"/>
			<geometry>
				<mesh filename="package://objects_description/keyboard/textured_objs/original-10.obj"/>
			</geometry>
		</collision>
	</link>
	<joint name="joint_4" type="prismatic">
		<origin xyz="-0.2305384505420256 0.04784422458054394 -0.11968905767549498"/>
		<axis xyz="0 -0.9938588581379322 -0.11065518560268853"/>
		<child link="link_4"/>
		<parent link="link_0"/>
		<limit lower="0" upper="0.01"/>
	</joint>
	<link name="link_5">
		<visual name="key-6">
			<origin xyz="0.2305384505420256 -0.04784422458054394 0.11968905767549498"/>
			<geometry>
				<mesh filename="package://objects_description/keyboard/textured_objs/original-4.obj"/>
			</geometry>
		</visual>
		<collision>
			<origin xyz="0.2305384505420256 -0.04784422458054394 0.11968905767549498"/>
			<geometry>
				<mesh filename="package://objects_description/keyboard/textured_objs/original-4.obj"/>
			</geometry>
		</collision>
	</link>
	<joint name="joint_5" type="prismatic">
		<origin xyz="-0.2305384505420256 0.04784422458054394 -0.11968905767549498"/>
		<axis xyz="0 -0.9938588581379322 -0.11065518560268853"/>
		<child link="link_5"/>
		<parent link="link_0"/>
		<limit lower="0" upper="0.01"/>
	</joint>
	<link name="link_6">
		<visual name="key-7">
			<origin xyz="0.2305384505420256 -0.04784422458054394 0.11968905767549498"/>
			<geometry>
				<mesh filename="package://objects_description/keyboard/textured_objs/original-2.obj"/>
			</geometry>
		</visual>
		<collision>
			<origin xyz="0.2305384505420256 -0.04784422458054394 0.11968905767549498"/>
			<geometry>
				<mesh filename="package://objects_description/keyboard/textured_objs/original-2.obj"/>
			</geometry>
		</collision>
	</link>
	<joint name="joint_6" type="prismatic">
		<origin xyz="-0.2305384505420256 0.04784422458054394 -0.11968905767549498"/>
		<axis xyz="0 -0.9938588581379322 -0.11065518560268853"/>
		<child link="link_6"/>
		<parent link="link_0"/>
		<limit lower="0" upper="0.01"/>
	</joint>
	<link name="link_7">
		<visual name="key-8">
			<origin xyz="0.2305384505420256 -0.04784422458054394 0.11968905767549498"/>
			<geometry>
				<mesh filename="package://objects_description/keyboard/textured_objs/original-23.obj"/>
			</geometry>
		</visual>
		<collision>
			<origin xyz="0.2305384505420256 -0.04784422458054394 0.11968905767549498"/>
			<geometry>
				<mesh filename="package://objects_description/keyboard/textured_objs/original-23.obj"/>
			</geometry>
		</collision>
	</link>
	<joint name="joint_7" type="prismatic">
		<origin xyz="-0.2305384505420256 0.04784422458054394 -0.11968905767549498"/>
		<axis xyz="0 -0.9938588581379322 -0.11065518560268853"/>
		<child link="link_7"/>
		<parent link="link_0"/>
		<limit lower="0" upper="0.01"/>
	</joint>
	<link name="link_8">
		<visual name="key-9">
			<origin xyz="0.2305384505420256 -0.04784422458054394 0.11968905767549498"/>
			<geometry>
				<mesh filename="package://objects_description/keyboard/textured_objs/original-17.obj"/>
			</geometry>
		</visual>
		<collision>
			<origin xyz="0.2305384505420256 -0.04784422458054394 0.11968905767549498"/>
			<geometry>
				<mesh filename="package://objects_description/keyboard/textured_objs/original-17.obj"/>
			</geometry>
		</collision>
	</link>
	<joint name="joint_8" type="prismatic">
		<origin xyz="-0.2305384505420256 0.04784422458054394 -0.11968905767549498"/>
		<axis xyz="0 -0.9938588581379322 -0.11065518560268853"/>
		<child link="link_8"/>
		<parent link="link_0"/>
		<limit lower="0" upper="0.01"/>
	</joint>
	<link name="link_9">
		<visual name="key-10">
			<origin xyz="0.2305384505420256 -0.04784422458054394 0.11968905767549498"/>
			<geometry>
				<mesh filename="package://objects_description/keyboard/textured_objs/original-7.obj"/>
			</geometry>
		</visual>
		<collision>
			<origin xyz="0.2305384505420256 -0.04784422458054394 0.11968905767549498"/>
			<geometry>
				<mesh filename="package://objects_description/keyboard/textured_objs/original-7.obj"/>
			</geometry>
		</collision>
	</link>
	<joint name="joint_9" type="prismatic">
		<origin xyz="-0.2305384505420256 0.04784422458054394 -0.11968905767549498"/>
		<axis xyz="0 -0.9938588581379322 -0.11065518560268853"/>
		<child link="link_9"/>
		<parent link="link_0"/>
		<limit lower="0" upper="0.01"/>
	</joint>
	<link name="link_10">
		<visual name="key-11">
			<origin xyz="0.2305384505420256 -0.04784422458054394 0.11968905767549498"/>
			<geometry>
				<mesh filename="package://objects_description/keyboard/textured_objs/original-9.obj"/>
			</geometry>
		</visual>
		<collision>
			<origin xyz="0.2305384505420256 -0.04784422458054394 0.11968905767549498"/>
			<geometry>
				<mesh filename="package://objects_description/keyboard/textured_objs/original-9.obj"/>
			</geometry>
		</collision>
	</link>
	<joint name="joint_10" type="prismatic">
		<origin xyz="-0.2305384505420256 0.04784422458054394 -0.11968905767549498"/>
		<axis xyz="0 -0.9938588581379322 -0.11065518560268853"/>
		<child link="link_10"/>
		<parent link="link_0"/>
		<limit lower="0" upper="0.01"/>
	</joint>
	<link name="link_11">
		<visual name="key-12">
			<origin xyz="0.2305384505420256 -0.04784422458054394 0.11968905767549498"/>
			<geometry>
				<mesh filename="package://objects_description/keyboard/textured_objs/original-19.obj"/>
			</geometry>
		</visual>
		<collision>
			<origin xyz="0.2305384505420256 -0.04784422458054394 0.11968905767549498"/>
			<geometry>
				<mesh filename="package://objects_description/keyboard/textured_objs/original-19.obj"/>
			</geometry>
		</collision>
	</link>
	<joint name="joint_11" type="prismatic">
		<origin xyz="-0.2305384505420256 0.04784422458054394 -0.11968905767549498"/>
		<axis xyz="0 -0.9938588581379322 -0.11065518560268853"/>
		<child link="link_11"/>
		<parent link="link_0"/>
		<limit lower="0" upper="0.01"/>
	</joint>
	<link name="link_12">
		<visual name="key-13">
			<origin xyz="0.2305384505420256 -0.04784422458054394 0.11968905767549498"/>
			<geometry>
				<mesh filename="package://objects_description/keyboard/textured_objs/original-36.obj"/>
			</geometry>
		</visual>
		<collision>
			<origin xyz="0.2305384505420256 -0.04784422458054394 0.11968905767549498"/>
			<geometry>
				<mesh filename="package://objects_description/keyboard/textured_objs/original-36.obj"/>
			</geometry>
		</collision>
	</link>
	<joint name="joint_12" type="prismatic">
		<origin xyz="-0.2305384505420256 0.04784422458054394 -0.11968905767549498"/>
		<axis xyz="0 -0.9938588581379322 -0.11065518560268853"/>
		<child link="link_12"/>
		<parent link="link_0"/>
		<limit lower="0" upper="0.01"/>
	</joint>
	<link name="link_13">
		<visual name="key-14">
			<origin xyz="0.2305384505420256 -0.04784422458054394 0.11968905767549498"/>
			<geometry>
				<mesh filename="package://objects_description/keyboard/textured_objs/original-78.obj"/>
			</geometry>
		</visual>
		<collision>
			<origin xyz="0.2305384505420256 -0.04784422458054394 0.11968905767549498"/>
			<geometry>
				<mesh filename="package://objects_description/keyboard/textured_objs/original-78.obj"/>
			</geometry>
		</collision>
	</link>
	<joint name="joint_13" type="prismatic">
		<origin xyz="-0.2305384505420256 0.04784422458054394 -0.11968905767549498"/>
		<axis xyz="0 -0.9938588581379322 -0.11065518560268853"/>
		<child link="link_13"/>
		<parent link="link_0"/>
		<limit lower="0" upper="0.01"/>
	</joint>
	<link name="link_14">
		<visual name="key-15">
			<origin xyz="0.2305384505420256 -0.04784422458054394 0.11968905767549498"/>
			<geometry>
				<mesh filename="package://objects_description/keyboard/textured_objs/original-64.obj"/>
			</geometry>
		</visual>
		<collision>
			<origin xyz="0.2305384505420256 -0.04784422458054394 0.11968905767549498"/>
			<geometry>
				<mesh filename="package://objects_description/keyboard/textured_objs/original-64.obj"/>
			</geometry>
		</collision>
	</link>
	<joint name="joint_14" type="prismatic">
		<origin xyz="-0.2305384505420256 0.04784422458054394 -0.11968905767549498"/>
		<axis xyz="0 -0.9938588581379322 -0.11065518560268853"/>
		<child link="link_14"/>
		<parent link="link_0"/>
		<limit lower="0" upper="0.01"/>
	</joint>
	<link name="link_15">
		<visual name="key-16">
			<origin xyz="0.2305384505420256 -0.04784422458054394 0.11968905767549498"/>
			<geometry>
				<mesh filename="package://objects_description/keyboard/textured_objs/original-55.obj"/>
			</geometry>
		</visual>
		<collision>
			<origin xyz="0.2305384505420256 -0.04784422458054394 0.11968905767549498"/>
			<geometry>
				<mesh filename="package://objects_description/keyboard/textured_objs/original-55.obj"/>
			</geometry>
		</collision>
	</link>
	<joint name="joint_15" type="prismatic">
		<origin xyz="-0.2305384505420256 0.04784422458054394 -0.11968905767549498"/>
		<axis xyz="0 -0.9938588581379322 -0.11065518560268853"/>
		<child link="link_15"/>
		<parent link="link_0"/>
		<limit lower="0" upper="0.01"/>
	</joint>
	<link name="link_16">
		<visual name="key-17">
			<origin xyz="0.2305384505420256 -0.04784422458054394 0.11968905767549498"/>
			<geometry>
				<mesh filename="package://objects_description/keyboard/textured_objs/original-39.obj"/>
			</geometry>
		</visual>
		<collision>
			<origin xyz="0.2305384505420256 -0.04784422458054394 0.11968905767549498"/>
			<geometry>
				<mesh filename="package://objects_description/keyboard/textured_objs/original-39.obj"/>
			</geometry>
		</collision>
	</link>
	<joint name="joint_16" type="prismatic">
		<origin xyz="-0.2305384505420256 0.04784422458054394 -0.11968905767549498"/>
		<axis xyz="0 -0.9938588581379322 -0.11065518560268853"/>
		<child link="link_16"/>
		<parent link="link_0"/>
		<limit lower="0" upper="0.01"/>
	</joint>
	<link name="link_17">
		<visual name="key-18">
			<origin xyz="0.2305384505420256 -0.04784422458054394 0.11968905767549498"/>
			<geometry>
				<mesh filename="package://objects_description/keyboard/textured_objs/original-35.obj"/>
			</geometry>
		</visual>
		<collision>
			<origin xyz="0.2305384505420256 -0.04784422458054394 0.11968905767549498"/>
			<geometry>
				<mesh filename="package://objects_description/keyboard/textured_objs/original-35.obj"/>
			</geometry>
		</collision>
	</link>
	<joint name="joint_17" type="prismatic">
		<origin xyz="-0.2305384505420256 0.04784422458054394 -0.11968905767549498"/>
		<axis xyz="0 -0.9938588581379322 -0.11065518560268853"/>
		<child link="link_17"/>
		<parent link="link_0"/>
		<limit lower="0" upper="0.01"/>
	</joint>
	<link name="link_18">
		<visual name="key-19">
			<origin xyz="0.2305384505420256 -0.04784422458054394 0.11968905767549498"/>
			<geometry>
				<mesh filename="package://objects_description/keyboard/textured_objs/original-40.obj"/>
			</geometry>
		</visual>
		<collision>
			<origin xyz="0.2305384505420256 -0.04784422458054394 0.11968905767549498"/>
			<geometry>
				<mesh filename="package://objects_description/keyboard/textured_objs/original-40.obj"/>
			</geometry>
		</collision>
	</link>
	<joint name="joint_18" type="prismatic">
		<origin xyz="-0.2305384505420256 0.04784422458054394 -0.11968905767549498"/>
		<axis xyz="0 -0.9938588581379322 -0.11065518560268853"/>
		<child link="link_18"/>
		<parent link="link_0"/>
		<limit lower="0" upper="0.01"/>
	</joint>
	<link name="link_19">
		<visual name="key-20">
			<origin xyz="0.2305384505420256 -0.04784422458054394 0.11968905767549498"/>
			<geometry>
				<mesh filename="package://objects_description/keyboard/textured_objs/original-54.obj"/>
			</geometry>
		</visual>
		<collision>
			<origin xyz="0.2305384505420256 -0.04784422458054394 0.11968905767549498"/>
			<geometry>
				<mesh filename="package://objects_description/keyboard/textured_objs/original-54.obj"/>
			</geometry>
		</collision>
	</link>
	<joint name="joint_19" type="prismatic">
		<origin xyz="-0.2305384505420256 0.04784422458054394 -0.11968905767549498"/>
		<axis xyz="0 -0.9938588581379322 -0.11065518560268853"/>
		<child link="link_19"/>
		<parent link="link_0"/>
		<limit lower="0" upper="0.01"/>
	</joint>
	<link name="link_20">
		<visual name="key-21">
			<origin xyz="0.2305384505420256 -0.04784422458054394 0.11968905767549498"/>
			<geometry>
				<mesh filename="package://objects_description/keyboard/textured_objs/original-37.obj"/>
			</geometry>
		</visual>
		<collision>
			<origin xyz="0.2305384505420256 -0.04784422458054394 0.11968905767549498"/>
			<geometry>
				<mesh filename="package://objects_description/keyboard/textured_objs/original-37.obj"/>
			</geometry>
		</collision>
	</link>
	<joint name="joint_20" type="prismatic">
		<origin xyz="-0.2305384505420256 0.04784422458054394 -0.11968905767549498"/>
		<axis xyz="0 -0.9938588581379322 -0.11065518560268853"/>
		<child link="link_20"/>
		<parent link="link_0"/>
		<limit lower="0" upper="0.01"/>
	</joint>
	<link name="link_21">
		<visual name="key-22">
			<origin xyz="0.2305384505420256 -0.04784422458054394 0.11968905767549498"/>
			<geometry>
				<mesh filename="package://objects_description/keyboard/textured_objs/original-53.obj"/>
			</geometry>
		</visual>
		<collision>
			<origin xyz="0.2305384505420256 -0.04784422458054394 0.11968905767549498"/>
			<geometry>
				<mesh filename="package://objects_description/keyboard/textured_objs/original-53.obj"/>
			</geometry>
		</collision>
	</link>
	<joint name="joint_21" type="prismatic">
		<origin xyz="-0.2305384505420256 0.04784422458054394 -0.11968905767549498"/>
		<axis xyz="0 -0.9938588581379322 -0.11065518560268853"/>
		<child link="link_21"/>
		<parent link="link_0"/>
		<limit lower="0" upper="0.01"/>
	</joint>
	<link name="link_22">
		<visual name="key-23">
			<origin xyz="0.2305384505420256 -0.04784422458054394 0.11968905767549498"/>
			<geometry>
				<mesh filename="package://objects_description/keyboard/textured_objs/original-52.obj"/>
			</geometry>
		</visual>
		<collision>
			<origin xyz="0.2305384505420256 -0.04784422458054394 0.11968905767549498"/>
			<geometry>
				<mesh filename="package://objects_description/keyboard/textured_objs/original-52.obj"/>
			</geometry>
		</collision>
	</link>
	<joint name="joint_22" type="prismatic">
		<origin xyz="-0.2305384505420256 0.04784422458054394 -0.11968905767549498"/>
		<axis xyz="0 -0.9938588581379322 -0.11065518560268853"/>
		<child link="link_22"/>
		<parent link="link_0"/>
		<limit lower="0" upper="0.01"/>
	</joint>
	<link name="link_23">
		<visual name="key-24">
			<origin xyz="0.2305384505420256 -0.04784422458054394 0.11968905767549498"/>
			<geometry>
				<mesh filename="package://objects_description/keyboard/textured_objs/original-38.obj"/>
			</geometry>
		</visual>
		<collision>
			<origin xyz="0.2305384505420256 -0.04784422458054394 0.11968905767549498"/>
			<geometry>
				<mesh filename="package://objects_description/keyboard/textured_objs/original-38.obj"/>
			</geometry>
		</collision>
	</link>
	<joint name="joint_23" type="prismatic">
		<origin xyz="-0.2305384505420256 0.04784422458054394 -0.11968905767549498"/>
		<axis xyz="0 -0.9938588581379322 -0.11065518560268853"/>
		<child link="link_23"/>
		<parent link="link_0"/>
		<limit lower="0" upper="0.01"/>
	</joint>
	<link name="link_24">
		<visual name="key-25">
			<origin xyz="0.2305384505420256 -0.04784422458054394 0.11968905767549498"/>
			<geometry>
				<mesh filename="package://objects_description/keyboard/textured_objs/original-51.obj"/>
			</geometry>
		</visual>
		<collision>
			<origin xyz="0.2305384505420256 -0.04784422458054394 0.11968905767549498"/>
			<geometry>
				<mesh filename="package://objects_description/keyboard/textured_objs/original-51.obj"/>
			</geometry>
		</collision>
	</link>
	<joint name="joint_24" type="prismatic">
		<origin xyz="-0.2305384505420256 0.04784422458054394 -0.11968905767549498"/>
		<axis xyz="0 -0.9938588581379322 -0.11065518560268853"/>
		<child link="link_24"/>
		<parent link="link_0"/>
		<limit lower="0" upper="0.01"/>
	</joint>
	<link name="link_25">
		<visual name="key-26">
			<origin xyz="0.2305384505420256 -0.04784422458054394 0.11968905767549498"/>
			<geometry>
				<mesh filename="package://objects_description/keyboard/textured_objs/original-13.obj"/>
			</geometry>
		</visual>
		<collision>
			<origin xyz="0.2305384505420256 -0.04784422458054394 0.11968905767549498"/>
			<geometry>
				<mesh filename="package://objects_description/keyboard/textured_objs/original-13.obj"/>
			</geometry>
		</collision>
	</link>
	<joint name="joint_25" type="prismatic">
		<origin xyz="-0.2305384505420256 0.04784422458054394 -0.11968905767549498"/>
		<axis xyz="0 -0.9938588581379322 -0.11065518560268853"/>
		<child link="link_25"/>
		<parent link="link_0"/>
		<limit lower="0" upper="0.01"/>
	</joint>
	<link name="link_26">
		<visual name="key-27">
			<origin xyz="0.2305384505420256 -0.04784422458054394 0.11968905767549498"/>
			<geometry>
				<mesh filename="package://objects_description/keyboard/textured_objs/original-32.obj"/>
			</geometry>
		</visual>
		<collision>
			<origin xyz="0.2305384505420256 -0.04784422458054394 0.11968905767549498"/>
			<geometry>
				<mesh filename="package://objects_description/keyboard/textured_objs/original-32.obj"/>
			</geometry>
		</collision>
	</link>
	<joint name="joint_26" type="prismatic">
		<origin xyz="-0.2305384505420256 0.04784422458054394 -0.11968905767549498"/>
		<axis xyz="0 -0.9938588581379322 -0.11065518560268853"/>
		<child link="link_26"/>
		<parent link="link_0"/>
		<limit lower="0" upper="0.01"/>
	</joint>
	<link name="link_27">
		<visual name="key-28">
			<origin xyz="0.2305384505420256 -0.04784422458054394 0.11968905767549498"/>
			<geometry>
				<mesh filename="package://objects_description/keyboard/textured_objs/original-50.obj"/>
			</geometry>
		</visual>
		<collision>
			<origin xyz="0.2305384505420256 -0.04784422458054394 0.11968905767549498"/>
			<geometry>
				<mesh filename="package://objects_description/keyboard/textured_objs/original-50.obj"/>
			</geometry>
		</collision>
	</link>
	<joint name="joint_27" type="prismatic">
		<origin xyz="-0.2305384505420256 0.04784422458054394 -0.11968905767549498"/>
		<axis xyz="0 -0.9938588581379322 -0.11065518560268853"/>
		<child link="link_27"/>
		<parent link="link_0"/>
		<limit lower="0" upper="0.01"/>
	</joint>
	<link name="link_28">
		<visual name="key-29">
			<origin xyz="0.2305384505420256 -0.04784422458054394 0.11968905767549498"/>
			<geometry>
				<mesh filename="package://objects_description/keyboard/textured_objs/original-49.obj"/>
			</geometry>
		</visual>
		<collision>
			<origin xyz="0.2305384505420256 -0.04784422458054394 0.11968905767549498"/>
			<geometry>
				<mesh filename="package://objects_description/keyboard/textured_objs/original-49.obj"/>
			</geometry>
		</collision>
	</link>
	<joint name="joint_28" type="prismatic">
		<origin xyz="-0.2305384505420256 0.04784422458054394 -0.11968905767549498"/>
		<axis xyz="0 -0.9938588581379322 -0.11065518560268853"/>
		<child link="link_28"/>
		<parent link="link_0"/>
		<limit lower="0" upper="0.01"/>
	</joint>
	<link name="link_29">
		<visual name="key-30">
			<origin xyz="0.2305384505420256 -0.04784422458054394 0.11968905767549498"/>
			<geometry>
				<mesh filename="package://objects_description/keyboard/textured_objs/original-47.obj"/>
			</geometry>
		</visual>
		<collision>
			<origin xyz="0.2305384505420256 -0.04784422458054394 0.11968905767549498"/>
			<geometry>
				<mesh filename="package://objects_description/keyboard/textured_objs/original-47.obj"/>
			</geometry>
		</collision>
	</link>
	<joint name="joint_29" type="prismatic">
		<origin xyz="-0.2305384505420256 0.04784422458054394 -0.11968905767549498"/>
		<axis xyz="0 -0.9938588581379322 -0.11065518560268853"/>
		<child link="link_29"/>
		<parent link="link_0"/>
		<limit lower="0" upper="0.01"/>
	</joint>
	<link name="link_30">
		<visual name="key-31">
			<origin xyz="0.2305384505420256 -0.04784422458054394 0.11968905767549498"/>
			<geometry>
				<mesh filename="package://objects_description/keyboard/textured_objs/original-43.obj"/>
			</geometry>
		</visual>
		<collision>
			<origin xyz="0.2305384505420256 -0.04784422458054394 0.11968905767549498"/>
			<geometry>
				<mesh filename="package://objects_description/keyboard/textured_objs/original-43.obj"/>
			</geometry>
		</collision>
	</link>
	<joint name="joint_30" type="prismatic">
		<origin xyz="-0.2305384505420256 0.04784422458054394 -0.11968905767549498"/>
		<axis xyz="0 -0.9938588581379322 -0.11065518560268853"/>
		<child link="link_30"/>
		<parent link="link_0"/>
		<limit lower="0" upper="0.01"/>
	</joint>
	<link name="link_31">
		<visual name="key-32">
			<origin xyz="0.2305384505420256 -0.04784422458054394 0.11968905767549498"/>
			<geometry>
				<mesh filename="package://objects_description/keyboard/textured_objs/original-67.obj"/>
			</geometry>
		</visual>
		<collision>
			<origin xyz="0.2305384505420256 -0.04784422458054394 0.11968905767549498"/>
			<geometry>
				<mesh filename="package://objects_description/keyboard/textured_objs/original-67.obj"/>
			</geometry>
		</collision>
	</link>
	<joint name="joint_31" type="prismatic">
		<origin xyz="-0.2305384505420256 0.04784422458054394 -0.11968905767549498"/>
		<axis xyz="0 -0.9938588581379322 -0.11065518560268853"/>
		<child link="link_31"/>
		<parent link="link_0"/>
		<limit lower="0" upper="0.01"/>
	</joint>
	<link name="link_32">
		<visual name="key-33">
			<origin xyz="0.2305384505420256 -0.04784422458054394 0.11968905767549498"/>
			<geometry>
				<mesh filename="package://objects_description/keyboard/textured_objs/original-44.obj"/>
			</geometry>
		</visual>
		<collision>
			<origin xyz="0.2305384505420256 -0.04784422458054394 0.11968905767549498"/>
			<geometry>
				<mesh filename="package://objects_description/keyboard/textured_objs/original-44.obj"/>
			</geometry>
		</collision>
	</link>
	<joint name="joint_32" type="prismatic">
		<origin xyz="-0.2305384505420256 0.04784422458054394 -0.11968905767549498"/>
		<axis xyz="0 -0.9938588581379322 -0.11065518560268853"/>
		<child link="link_32"/>
		<parent link="link_0"/>
		<limit lower="0" upper="0.01"/>
	</joint>
	<link name="link_33">
		<visual name="key-34">
			<origin xyz="0.2305384505420256 -0.04784422458054394 0.11968905767549498"/>
			<geometry>
				<mesh filename="package://objects_description/keyboard/textured_objs/original-59.obj"/>
			</geometry>
		</visual>
		<collision>
			<origin xyz="0.2305384505420256 -0.04784422458054394 0.11968905767549498"/>
			<geometry>
				<mesh filename="package://objects_description/keyboard/textured_objs/original-59.obj"/>
			</geometry>
		</collision>
	</link>
	<joint name="joint_33" type="prismatic">
		<origin xyz="-0.2305384505420256 0.04784422458054394 -0.11968905767549498"/>
		<axis xyz="0 -0.9938588581379322 -0.11065518560268853"/>
		<child link="link_33"/>
		<parent link="link_0"/>
		<limit lower="0" upper="0.01"/>
	</joint>
	<link name="link_34">
		<visual name="key-35">
			<origin xyz="0.2305384505420256 -0.04784422458054394 0.11968905767549498"/>
			<geometry>
				<mesh filename="package://objects_description/keyboard/textured_objs/original-65.obj"/>
			</geometry>
		</visual>
		<collision>
			<origin xyz="0.2305384505420256 -0.04784422458054394 0.11968905767549498"/>
			<geometry>
				<mesh filename="package://objects_description/keyboard/textured_objs/original-65.obj"/>
			</geometry>
		</collision>
	</link>
	<joint name="joint_34" type="prismatic">
		<origin xyz="-0.2305384505420256 0.04784422458054394 -0.11968905767549498"/>
		<axis xyz="0 -0.9938588581379322 -0.11065518560268853"/>
		<child link="link_34"/>
		<parent link="link_0"/>
		<limit lower="0" upper="0.01"/>
	</joint>
	<link name="link_35">
		<visual name="key-36">
			<origin xyz="0.2305384505420256 -0.04784422458054394 0.11968905767549498"/>
			<geometry>
				<mesh filename="package://objects_description/keyboard/textured_objs/original-57.obj"/>
			</geometry>
		</visual>
		<collision>
			<origin xyz="0.2305384505420256 -0.04784422458054394 0.11968905767549498"/>
			<geometry>
				<mesh filename="package://objects_description/keyboard/textured_objs/original-57.obj"/>
			</geometry>
		</collision>
	</link>
	<joint name="joint_35" type="prismatic">
		<origin xyz="-0.2305384505420256 0.04784422458054394 -0.11968905767549498"/>
		<axis xyz="0 -0.9938588581379322 -0.11065518560268853"/>
		<child link="link_35"/>
		<parent link="link_0"/>
		<limit lower="0" upper="0.01"/>
	</joint>
	<link name="link_36">
		<visual name="key-37">
			<origin xyz="0.2305384505420256 -0.04784422458054394 0.11968905767549498"/>
			<geometry>
				<mesh filename="package://objects_description/keyboard/textured_objs/original-79.obj"/>
			</geometry>
		</visual>
		<collision>
			<origin xyz="0.2305384505420256 -0.04784422458054394 0.11968905767549498"/>
			<geometry>
				<mesh filename="package://objects_description/keyboard/textured_objs/original-79.obj"/>
			</geometry>
		</collision>
	</link>
	<joint name="joint_36" type="prismatic">
		<origin xyz="-0.2305384505420256 0.04784422458054394 -0.11968905767549498"/>
		<axis xyz="0 -0.9938588581379322 -0.11065518560268853"/>
		<child link="link_36"/>
		<parent link="link_0"/>
		<limit lower="0" upper="0.01"/>
	</joint>
	<link name="link_37">
		<visual name="key-38">
			<origin xyz="0.2305384505420256 -0.04784422458054394 0.11968905767549498"/>
			<geometry>
				<mesh filename="package://objects_description/keyboard/textured_objs/original-34.obj"/>
			</geometry>
		</visual>
		<collision>
			<origin xyz="0.2305384505420256 -0.04784422458054394 0.11968905767549498"/>
			<geometry>
				<mesh filename="package://objects_description/keyboard/textured_objs/original-34.obj"/>
			</geometry>
		</collision>
	</link>
	<joint name="joint_37" type="prismatic">
		<origin xyz="-0.2305384505420256 0.04784422458054394 -0.11968905767549498"/>
		<axis xyz="0 -0.9938588581379322 -0.11065518560268853"/>
		<child link="link_37"/>
		<parent link="link_0"/>
		<limit lower="0" upper="0.01"/>
	</joint>
	<link name="link_38">
		<visual name="key-39">
			<origin xyz="0.2305384505420256 -0.04784422458054394 0.11968905767549498"/>
			<geometry>
				<mesh filename="package://objects_description/keyboard/textured_objs/original-16.obj"/>
			</geometry>
		</visual>
		<collision>
			<origin xyz="0.2305384505420256 -0.04784422458054394 0.11968905767549498"/>
			<geometry>
				<mesh filename="package://objects_description/keyboard/textured_objs/original-16.obj"/>
			</geometry>
		</collision>
	</link>
	<joint name="joint_38" type="prismatic">
		<origin xyz="-0.2305384505420256 0.04784422458054394 -0.11968905767549498"/>
		<axis xyz="0 -0.9938588581379322 -0.11065518560268853"/>
		<child link="link_38"/>
		<parent link="link_0"/>
		<limit lower="0" upper="0.01"/>
	</joint>
	<link name="link_39">
		<visual name="key-40">
			<origin xyz="0.2305384505420256 -0.04784422458054394 0.11968905767549498"/>
			<geometry>
				<mesh filename="package://objects_description/keyboard/textured_objs/original-3.obj"/>
			</geometry>
		</visual>
		<collision>
			<origin xyz="0.2305384505420256 -0.04784422458054394 0.11968905767549498"/>
			<geometry>
				<mesh filename="package://objects_description/keyboard/textured_objs/original-3.obj"/>
			</geometry>
		</collision>
	</link>
	<joint name="joint_39" type="prismatic">
		<origin xyz="-0.2305384505420256 0.04784422458054394 -0.11968905767549498"/>
		<axis xyz="0 -0.9938588581379322 -0.11065518560268853"/>
		<child link="link_39"/>
		<parent link="link_0"/>
		<limit lower="0" upper="0.01"/>
	</joint>
	<link name="link_40">
		<visual name="key-41">
			<origin xyz="0.2305384505420256 -0.04784422458054394 0.11968905767549498"/>
			<geometry>
				<mesh filename="package://objects_description/keyboard/textured_objs/original-5.obj"/>
			</geometry>
		</visual>
		<collision>
			<origin xyz="0.2305384505420256 -0.04784422458054394 0.11968905767549498"/>
			<geometry>
				<mesh filename="package://objects_description/keyboard/textured_objs/original-5.obj"/>
			</geometry>
		</collision>
	</link>
	<joint name="joint_40" type="prismatic">
		<origin xyz="-0.2305384505420256 0.04784422458054394 -0.11968905767549498"/>
		<axis xyz="0 -0.9938588581379322 -0.11065518560268853"/>
		<child link="link_40"/>
		<parent link="link_0"/>
		<limit lower="0" upper="0.01"/>
	</joint>
	<link name="link_41">
		<visual name="key-42">
			<origin xyz="0.2305384505420256 -0.04784422458054394 0.11968905767549498"/>
			<geometry>
				<mesh filename="package://objects_description/keyboard/textured_objs/original-56.obj"/>
			</geometry>
		</visual>
		<collision>
			<origin xyz="0.2305384505420256 -0.04784422458054394 0.11968905767549498"/>
			<geometry>
				<mesh filename="package://objects_description/keyboard/textured_objs/original-56.obj"/>
			</geometry>
		</collision>
	</link>
	<joint name="joint_41" type="prismatic">
		<origin xyz="-0.2305384505420256 0.04784422458054394 -0.11968905767549498"/>
		<axis xyz="0 -0.9938588581379322 -0.11065518560268853"/>
		<child link="link_41"/>
		<parent link="link_0"/>
		<limit lower="0" upper="0.01"/>
	</joint>
	<link name="link_42">
		<visual name="key-43">
			<origin xyz="0.2305384505420256 -0.04784422458054394 0.11968905767549498"/>
			<geometry>
				<mesh filename="package://objects_description/keyboard/textured_objs/original-21.obj"/>
			</geometry>
		</visual>
		<collision>
			<origin xyz="0.2305384505420256 -0.04784422458054394 0.11968905767549498"/>
			<geometry>
				<mesh filename="package://objects_description/keyboard/textured_objs/original-21.obj"/>
			</geometry>
		</collision>
	</link>
	<joint name="joint_42" type="prismatic">
		<origin xyz="-0.2305384505420256 0.04784422458054394 -0.11968905767549498"/>
		<axis xyz="0 -0.9938588581379322 -0.11065518560268853"/>
		<child link="link_42"/>
		<parent link="link_0"/>
		<limit lower="0" upper="0.01"/>
	</joint>
	<link name="link_43">
		<visual name="key-44">
			<origin xyz="0.2305384505420256 -0.04784422458054394 0.11968905767549498"/>
			<geometry>
				<mesh filename="package://objects_description/keyboard/textured_objs/original-58.obj"/>
			</geometry>
		</visual>
		<collision>
			<origin xyz="0.2305384505420256 -0.04784422458054394 0.11968905767549498"/>
			<geometry>
				<mesh filename="package://objects_description/keyboard/textured_objs/original-58.obj"/>
			</geometry>
		</collision>
	</link>
	<joint name="joint_43" type="prismatic">
		<origin xyz="-0.2305384505420256 0.04784422458054394 -0.11968905767549498"/>
		<axis xyz="0 -0.9938588581379322 -0.11065518560268853"/>
		<child link="link_43"/>
		<parent link="link_0"/>
		<limit lower="0" upper="0.01"/>
	</joint>
	<link name="link_44">
		<visual name="key-45">
			<origin xyz="0.2305384505420256 -0.04784422458054394 0.11968905767549498"/>
			<geometry>
				<mesh filename="package://objects_description/keyboard/textured_objs/original-66.obj"/>
			</geometry>
		</visual>
		<collision>
			<origin xyz="0.2305384505420256 -0.04784422458054394 0.11968905767549498"/>
			<geometry>
				<mesh filename="package://objects_description/keyboard/textured_objs/original-66.obj"/>
			</geometry>
		</collision>
	</link>
	<joint name="joint_44" type="prismatic">
		<origin xyz="-0.2305384505420256 0.04784422458054394 -0.11968905767549498"/>
		<axis xyz="0 -0.9938588581379322 -0.11065518560268853"/>
		<child link="link_44"/>
		<parent link="link_0"/>
		<limit lower="0" upper="0.01"/>
	</joint>
	<link name="link_45">
		<visual name="key-46">
			<origin xyz="0.2305384505420256 -0.04784422458054394 0.11968905767549498"/>
			<geometry>
				<mesh filename="package://objects_description/keyboard/textured_objs/original-24.obj"/>
			</geometry>
		</visual>
		<collision>
			<origin xyz="0.2305384505420256 -0.04784422458054394 0.11968905767549498"/>
			<geometry>
				<mesh filename="package://objects_description/keyboard/textured_objs/original-24.obj"/>
			</geometry>
		</collision>
	</link>
	<joint name="joint_45" type="prismatic">
		<origin xyz="-0.2305384505420256 0.04784422458054394 -0.11968905767549498"/>
		<axis xyz="0 -0.9938588581379322 -0.11065518560268853"/>
		<child link="link_45"/>
		<parent link="link_0"/>
		<limit lower="0" upper="0.01"/>
	</joint>
	<link name="link_46">
		<visual name="key-47">
			<origin xyz="0.2305384505420256 -0.04784422458054394 0.11968905767549498"/>
			<geometry>
				<mesh filename="package://objects_description/keyboard/textured_objs/original-69.obj"/>
			</geometry>
		</visual>
		<collision>
			<origin xyz="0.2305384505420256 -0.04784422458054394 0.11968905767549498"/>
			<geometry>
				<mesh filename="package://objects_description/keyboard/textured_objs/original-69.obj"/>
			</geometry>
		</collision>
	</link>
	<joint name="joint_46" type="prismatic">
		<origin xyz="-0.2305384505420256 0.04784422458054394 -0.11968905767549498"/>
		<axis xyz="0 -0.9938588581379322 -0.11065518560268853"/>
		<child link="link_46"/>
		<parent link="link_0"/>
		<limit lower="0" upper="0.01"/>
	</joint>
	<link name="link_47">
		<visual name="key-48">
			<origin xyz="0.2305384505420256 -0.04784422458054394 0.11968905767549498"/>
			<geometry>
				<mesh filename="package://objects_description/keyboard/textured_objs/original-70.obj"/>
			</geometry>
		</visual>
		<collision>
			<origin xyz="0.2305384505420256 -0.04784422458054394 0.11968905767549498"/>
			<geometry>
				<mesh filename="package://objects_description/keyboard/textured_objs/original-70.obj"/>
			</geometry>
		</collision>
	</link>
	<joint name="joint_47" type="prismatic">
		<origin xyz="-0.2305384505420256 0.04784422458054394 -0.11968905767549498"/>
		<axis xyz="0 -0.9938588581379322 -0.11065518560268853"/>
		<child link="link_47"/>
		<parent link="link_0"/>
		<limit lower="0" upper="0.01"/>
	</joint>
	<link name="link_48">
		<visual name="key-49">
			<origin xyz="0.2305384505420256 -0.04784422458054394 0.11968905767549498"/>
			<geometry>
				<mesh filename="package://objects_description/keyboard/textured_objs/original-46.obj"/>
			</geometry>
		</visual>
		<collision>
			<origin xyz="0.2305384505420256 -0.04784422458054394 0.11968905767549498"/>
			<geometry>
				<mesh filename="package://objects_description/keyboard/textured_objs/original-46.obj"/>
			</geometry>
		</collision>
	</link>
	<joint name="joint_48" type="prismatic">
		<origin xyz="-0.2305384505420256 0.04784422458054394 -0.11968905767549498"/>
		<axis xyz="0 -0.9938588581379322 -0.11065518560268853"/>
		<child link="link_48"/>
		<parent link="link_0"/>
		<limit lower="0" upper="0.01"/>
	</joint>
	<link name="link_49">
		<visual name="key-50">
			<origin xyz="0.2305384505420256 -0.04784422458054394 0.11968905767549498"/>
			<geometry>
				<mesh filename="package://objects_description/keyboard/textured_objs/original-45.obj"/>
			</geometry>
		</visual>
		<collision>
			<origin xyz="0.2305384505420256 -0.04784422458054394 0.11968905767549498"/>
			<geometry>
				<mesh filename="package://objects_description/keyboard/textured_objs/original-45.obj"/>
			</geometry>
		</collision>
	</link>
	<joint name="joint_49" type="prismatic">
		<origin xyz="-0.2305384505420256 0.04784422458054394 -0.11968905767549498"/>
		<axis xyz="0 -0.9938588581379322 -0.11065518560268853"/>
		<child link="link_49"/>
		<parent link="link_0"/>
		<limit lower="0" upper="0.01"/>
	</joint>
	<link name="link_50">
		<visual name="key-51">
			<origin xyz="0.2305384505420256 -0.04784422458054394 0.11968905767549498"/>
			<geometry>
				<mesh filename="package://objects_description/keyboard/textured_objs/original-48.obj"/>
			</geometry>
		</visual>
		<collision>
			<origin xyz="0.2305384505420256 -0.04784422458054394 0.11968905767549498"/>
			<geometry>
				<mesh filename="package://objects_description/keyboard/textured_objs/original-48.obj"/>
			</geometry>
		</collision>
	</link>
	<joint name="joint_50" type="prismatic">
		<origin xyz="-0.2305384505420256 0.04784422458054394 -0.11968905767549498"/>
		<axis xyz="0 -0.9938588581379322 -0.11065518560268853"/>
		<child link="link_50"/>
		<parent link="link_0"/>
		<limit lower="0" upper="0.01"/>
	</joint>
	<link name="link_51">
		<visual name="key-52">
			<origin xyz="0.2305384505420256 -0.04784422458054394 0.11968905767549498"/>
			<geometry>
				<mesh filename="package://objects_description/keyboard/textured_objs/original-41.obj"/>
			</geometry>
		</visual>
		<collision>
			<origin xyz="0.2305384505420256 -0.04784422458054394 0.11968905767549498"/>
			<geometry>
				<mesh filename="package://objects_description/keyboard/textured_objs/original-41.obj"/>
			</geometry>
		</collision>
	</link>
	<joint name="joint_51" type="prismatic">
		<origin xyz="-0.2305384505420256 0.04784422458054394 -0.11968905767549498"/>
		<axis xyz="0 -0.9938588581379322 -0.11065518560268853"/>
		<child link="link_51"/>
		<parent link="link_0"/>
		<limit lower="0" upper="0.01"/>
	</joint>
	<link name="link_52">
		<visual name="key-53">
			<origin xyz="0.2305384505420256 -0.04784422458054394 0.11968905767549498"/>
			<geometry>
				<mesh filename="package://objects_description/keyboard/textured_objs/original-33.obj"/>
			</geometry>
		</visual>
		<collision>
			<origin xyz="0.2305384505420256 -0.04784422458054394 0.11968905767549498"/>
			<geometry>
				<mesh filename="package://objects_description/keyboard/textured_objs/original-33.obj"/>
			</geometry>
		</collision>
	</link>
	<joint name="joint_52" type="prismatic">
		<origin xyz="-0.2305384505420256 0.04784422458054394 -0.11968905767549498"/>
		<axis xyz="0 -0.9938588581379322 -0.11065518560268853"/>
		<child link="link_52"/>
		<parent link="link_0"/>
		<limit lower="0" upper="0.01"/>
	</joint>
	<link name="link_53">
		<visual name="key-54">
			<origin xyz="0.2305384505420256 -0.04784422458054394 0.11968905767549498"/>
			<geometry>
				<mesh filename="package://objects_description/keyboard/textured_objs/original-28.obj"/>
			</geometry>
		</visual>
		<collision>
			<origin xyz="0.2305384505420256 -0.04784422458054394 0.11968905767549498"/>
			<geometry>
				<mesh filename="package://objects_description/keyboard/textured_objs/original-28.obj"/>
			</geometry>
		</collision>
	</link>
	<joint name="joint_53" type="prismatic">
		<origin xyz="-0.2305384505420256 0.04784422458054394 -0.11968905767549498"/>
		<axis xyz="0 -0.9938588581379322 -0.11065518560268853"/>
		<child link="link_53"/>
		<parent link="link_0"/>
		<limit lower="0" upper="0.01"/>
	</joint>
	<link name="link_54">
		<visual name="key-55">
			<origin xyz="0.2305384505420256 -0.04784422458054394 0.11968905767549498"/>
			<geometry>
				<mesh filename="package://objects_description/keyboard/textured_objs/original-42.obj"/>
			</geometry>
		</visual>
		<collision>
			<origin xyz="0.2305384505420256 -0.04784422458054394 0.11968905767549498"/>
			<geometry>
				<mesh filename="package://objects_description/keyboard/textured_objs/original-42.obj"/>
			</geometry>
		</collision>
	</link>
	<joint name="joint_54" type="prismatic">
		<origin xyz="-0.2305384505420256 0.04784422458054394 -0.11968905767549498"/>
		<axis xyz="0 -0.9938588581379322 -0.11065518560268853"/>
		<child link="link_54"/>
		<parent link="link_0"/>
		<limit lower="0" upper="0.01"/>
	</joint>
	<link name="link_55">
		<visual name="key-56">
			<origin xyz="0.2305384505420256 -0.04784422458054394 0.11968905767549498"/>
			<geometry>
				<mesh filename="package://objects_description/keyboard/textured_objs/original-74.obj"/>
			</geometry>
		</visual>
		<collision>
			<origin xyz="0.2305384505420256 -0.04784422458054394 0.11968905767549498"/>
			<geometry>
				<mesh filename="package://objects_description/keyboard/textured_objs/original-74.obj"/>
			</geometry>
		</collision>
	</link>
	<joint name="joint_55" type="prismatic">
		<origin xyz="-0.2305384505420256 0.04784422458054394 -0.11968905767549498"/>
		<axis xyz="0 -0.9938588581379322 -0.11065518560268853"/>
		<child link="link_55"/>
		<parent link="link_0"/>
		<limit lower="0" upper="0.01"/>
	</joint>
	<link name="link_56">
		<visual name="key-57">
			<origin xyz="0.2305384505420256 -0.04784422458054394 0.11968905767549498"/>
			<geometry>
				<mesh filename="package://objects_description/keyboard/textured_objs/original-68.obj"/>
			</geometry>
		</visual>
		<collision>
			<origin xyz="0.2305384505420256 -0.04784422458054394 0.11968905767549498"/>
			<geometry>
				<mesh filename="package://objects_description/keyboard/textured_objs/original-68.obj"/>
			</geometry>
		</collision>
	</link>
	<joint name="joint_56" type="prismatic">
		<origin xyz="-0.2305384505420256 0.04784422458054394 -0.11968905767549498"/>
		<axis xyz="0 -0.9938588581379322 -0.11065518560268853"/>
		<child link="link_56"/>
		<parent link="link_0"/>
		<limit lower="0" upper="0.01"/>
	</joint>
	<link name="link_57">
		<visual name="key-58">
			<origin xyz="0.2305384505420256 -0.04784422458054394 0.11968905767549498"/>
			<geometry>
				<mesh filename="package://objects_description/keyboard/textured_objs/original-22.obj"/>
			</geometry>
		</visual>
		<collision>
			<origin xyz="0.2305384505420256 -0.04784422458054394 0.11968905767549498"/>
			<geometry>
				<mesh filename="package://objects_description/keyboard/textured_objs/original-22.obj"/>
			</geometry>
		</collision>
	</link>
	<joint name="joint_57" type="prismatic">
		<origin xyz="-0.2305384505420256 0.04784422458054394 -0.11968905767549498"/>
		<axis xyz="0 -0.9938588581379322 -0.11065518560268853"/>
		<child link="link_57"/>
		<parent link="link_0"/>
		<limit lower="0" upper="0.01"/>
	</joint>
	<link name="link_58">
		<visual name="key-59">
			<origin xyz="0.2305384505420256 -0.04784422458054394 0.11968905767549498"/>
			<geometry>
				<mesh filename="package://objects_description/keyboard/textured_objs/original-77.obj"/>
			</geometry>
		</visual>
		<collision>
			<origin xyz="0.2305384505420256 -0.04784422458054394 0.11968905767549498"/>
			<geometry>
				<mesh filename="package://objects_description/keyboard/textured_objs/original-77.obj"/>
			</geometry>
		</collision>
	</link>
	<joint name="joint_58" type="prismatic">
		<origin xyz="-0.2305384505420256 0.04784422458054394 -0.11968905767549498"/>
		<axis xyz="0 -0.9938588581379322 -0.11065518560268853"/>
		<child link="link_58"/>
		<parent link="link_0"/>
		<limit lower="0" upper="0.01"/>
	</joint>
	<link name="link_59">
		<visual name="key-60">
			<origin xyz="0.2305384505420256 -0.04784422458054394 0.11968905767549498"/>
			<geometry>
				<mesh filename="package://objects_description/keyboard/textured_objs/original-76.obj"/>
			</geometry>
		</visual>
		<collision>
			<origin xyz="0.2305384505420256 -0.04784422458054394 0.11968905767549498"/>
			<geometry>
				<mesh filename="package://objects_description/keyboard/textured_objs/original-76.obj"/>
			</geometry>
		</collision>
	</link>
	<joint name="joint_59" type="prismatic">
		<origin xyz="-0.2305384505420256 0.04784422458054394 -0.11968905767549498"/>
		<axis xyz="0 -0.9938588581379322 -0.11065518560268853"/>
		<child link="link_59"/>
		<parent link="link_0"/>
		<limit lower="0" upper="0.01"/>
	</joint>
	<link name="link_60">
		<visual name="key-61">
			<origin xyz="0.2305384505420256 -0.04784422458054394 0.11968905767549498"/>
			<geometry>
				<mesh filename="package://objects_description/keyboard/textured_objs/original-75.obj"/>
			</geometry>
		</visual>
		<collision>
			<origin xyz="0.2305384505420256 -0.04784422458054394 0.11968905767549498"/>
			<geometry>
				<mesh filename="package://objects_description/keyboard/textured_objs/original-75.obj"/>
			</geometry>
		</collision>
	</link>
	<joint name="joint_60" type="prismatic">
		<origin xyz="-0.2305384505420256 0.04784422458054394 -0.11968905767549498"/>
		<axis xyz="0 -0.9938588581379322 -0.11065518560268853"/>
		<child link="link_60"/>
		<parent link="link_0"/>
		<limit lower="0" upper="0.01"/>
	</joint>
	<link name="link_61">
		<visual name="key-62">
			<origin xyz="0.2305384505420256 -0.04784422458054394 0.11968905767549498"/>
			<geometry>
				<mesh filename="package://objects_description/keyboard/textured_objs/original-8.obj"/>
			</geometry>
		</visual>
		<collision>
			<origin xyz="0.2305384505420256 -0.04784422458054394 0.11968905767549498"/>
			<geometry>
				<mesh filename="package://objects_description/keyboard/textured_objs/original-8.obj"/>
			</geometry>
		</collision>
	</link>
	<joint name="joint_61" type="prismatic">
		<origin xyz="-0.2305384505420256 0.04784422458054394 -0.11968905767549498"/>
		<axis xyz="0 -0.9938588581379322 -0.11065518560268853"/>
		<child link="link_61"/>
		<parent link="link_0"/>
		<limit lower="0" upper="0.01"/>
	</joint>
	<link name="link_62">
		<visual name="key-63">
			<origin xyz="0.2305384505420256 -0.04784422458054394 0.11968905767549498"/>
			<geometry>
				<mesh filename="package://objects_description/keyboard/textured_objs/original-62.obj"/>
			</geometry>
		</visual>
		<collision>
			<origin xyz="0.2305384505420256 -0.04784422458054394 0.11968905767549498"/>
			<geometry>
				<mesh filename="package://objects_description/keyboard/textured_objs/original-62.obj"/>
			</geometry>
		</collision>
	</link>
	<joint name="joint_62" type="prismatic">
		<origin xyz="-0.2305384505420256 0.04784422458054394 -0.11968905767549498"/>
		<axis xyz="0 -0.9938588581379322 -0.11065518560268853"/>
		<child link="link_62"/>
		<parent link="link_0"/>
		<limit lower="0" upper="0.01"/>
	</joint>
	<link name="link_63">
		<visual name="key-64">
			<origin xyz="0.2305384505420256 -0.04784422458054394 0.11968905767549498"/>
			<geometry>
				<mesh filename="package://objects_description/keyboard/textured_objs/original-30.obj"/>
			</geometry>
		</visual>
		<collision>
			<origin xyz="0.2305384505420256 -0.04784422458054394 0.11968905767549498"/>
			<geometry>
				<mesh filename="package://objects_description/keyboard/textured_objs/original-30.obj"/>
			</geometry>
		</collision>
	</link>
	<joint name="joint_63" type="prismatic">
		<origin xyz="-0.2305384505420256 0.04784422458054394 -0.11968905767549498"/>
		<axis xyz="0 -0.9938588581379322 -0.11065518560268853"/>
		<child link="link_63"/>
		<parent link="link_0"/>
		<limit lower="0" upper="0.01"/>
	</joint>
	<link name="link_64">
		<visual name="key-65">
			<origin xyz="0.2305384505420256 -0.04784422458054394 0.11968905767549498"/>
			<geometry>
				<mesh filename="package://objects_description/keyboard/textured_objs/original-73.obj"/>
			</geometry>
		</visual>
		<collision>
			<origin xyz="0.2305384505420256 -0.04784422458054394 0.11968905767549498"/>
			<geometry>
				<mesh filename="package://objects_description/keyboard/textured_objs/original-73.obj"/>
			</geometry>
		</collision>
	</link>
	<joint name="joint_64" type="prismatic">
		<origin xyz="-0.2305384505420256 0.04784422458054394 -0.11968905767549498"/>
		<axis xyz="0 -0.9938588581379322 -0.11065518560268853"/>
		<child link="link_64"/>
		<parent link="link_0"/>
		<limit lower="0" upper="0.01"/>
	</joint>
	<link name="link_65">
		<visual name="key-66">
			<origin xyz="0.2305384505420256 -0.04784422458054394 0.11968905767549498"/>
			<geometry>
				<mesh filename="package://objects_description/keyboard/textured_objs/original-27.obj"/>
			</geometry>
		</visual>
		<collision>
			<origin xyz="0.2305384505420256 -0.04784422458054394 0.11968905767549498"/>
			<geometry>
				<mesh filename="package://objects_description/keyboard/textured_objs/original-27.obj"/>
			</geometry>
		</collision>
	</link>
	<joint name="joint_65" type="prismatic">
		<origin xyz="-0.2305384505420256 0.04784422458054394 -0.11968905767549498"/>
		<axis xyz="0 -0.9938588581379322 -0.11065518560268853"/>
		<child link="link_65"/>
		<parent link="link_0"/>
		<limit lower="0" upper="0.01"/>
	</joint>
	<link name="link_66">
		<visual name="key-67">
			<origin xyz="0.2305384505420256 -0.04784422458054394 0.11968905767549498"/>
			<geometry>
				<mesh filename="package://objects_description/keyboard/textured_objs/original-61.obj"/>
			</geometry>
		</visual>
		<collision>
			<origin xyz="0.2305384505420256 -0.04784422458054394 0.11968905767549498"/>
			<geometry>
				<mesh filename="package://objects_description/keyboard/textured_objs/original-61.obj"/>
			</geometry>
		</collision>
	</link>
	<joint name="joint_66" type="prismatic">
		<origin xyz="-0.2305384505420256 0.04784422458054394 -0.11968905767549498"/>
		<axis xyz="0 -0.9938588581379322 -0.11065518560268853"/>
		<child link="link_66"/>
		<parent link="link_0"/>
		<limit lower="0" upper="0.01"/>
	</joint>
	<link name="link_67">
		<visual name="key-68">
			<origin xyz="0.2305384505420256 -0.04784422458054394 0.11968905767549498"/>
			<geometry>
				<mesh filename="package://objects_description/keyboard/textured_objs/original-26.obj"/>
			</geometry>
		</visual>
		<collision>
			<origin xyz="0.2305384505420256 -0.04784422458054394 0.11968905767549498"/>
			<geometry>
				<mesh filename="package://objects_description/keyboard/textured_objs/original-26.obj"/>
			</geometry>
		</collision>
	</link>
	<joint name="joint_67" type="prismatic">
		<origin xyz="-0.2305384505420256 0.04784422458054394 -0.11968905767549498"/>
		<axis xyz="0 -0.9938588581379322 -0.11065518560268853"/>
		<child link="link_67"/>
		<parent link="link_0"/>
		<limit lower="0" upper="0.01"/>
	</joint>
	<link name="link_68">
		<visual name="key-69">
			<origin xyz="0.2305384505420256 -0.04784422458054394 0.11968905767549498"/>
			<geometry>
				<mesh filename="package://objects_description/keyboard/textured_objs/original-29.obj"/>
			</geometry>
		</visual>
		<collision>
			<origin xyz="0.2305384505420256 -0.04784422458054394 0.11968905767549498"/>
			<geometry>
				<mesh filename="package://objects_description/keyboard/textured_objs/original-29.obj"/>
			</geometry>
		</collision>
	</link>
	<joint name="joint_68" type="prismatic">
		<origin xyz="-0.2305384505420256 0.04784422458054394 -0.11968905767549498"/>
		<axis xyz="0 -0.9938588581379322 -0.11065518560268853"/>
		<child link="link_68"/>
		<parent link="link_0"/>
		<limit lower="0" upper="0.01"/>
	</joint>
	<link name="link_69">
		<visual name="key-70">
			<origin xyz="0.2305384505420256 -0.04784422458054394 0.11968905767549498"/>
			<geometry>
				<mesh filename="package://objects_description/keyboard/textured_objs/original-63.obj"/>
			</geometry>
		</visual>
		<collision>
			<origin xyz="0.2305384505420256 -0.04784422458054394 0.11968905767549498"/>
			<geometry>
				<mesh filename="package://objects_description/keyboard/textured_objs/original-63.obj"/>
			</geometry>
		</collision>
	</link>
	<joint name="joint_69" type="prismatic">
		<origin xyz="-0.2305384505420256 0.04784422458054394 -0.11968905767549498"/>
		<axis xyz="0 -0.9938588581379322 -0.11065518560268853"/>
		<child link="link_69"/>
		<parent link="link_0"/>
		<limit lower="0" upper="0.01"/>
	</joint>
	<link name="link_70">
		<visual name="key-71">
			<origin xyz="0.2305384505420256 -0.04784422458054394 0.11968905767549498"/>
			<geometry>
				<mesh filename="package://objects_description/keyboard/textured_objs/original-12.obj"/>
			</geometry>
		</visual>
		<collision>
			<origin xyz="0.2305384505420256 -0.04784422458054394 0.11968905767549498"/>
			<geometry>
				<mesh filename="package://objects_description/keyboard/textured_objs/original-12.obj"/>
			</geometry>
		</collision>
	</link>
	<joint name="joint_70" type="prismatic">
		<origin xyz="-0.2305384505420256 0.04784422458054394 -0.11968905767549498"/>
		<axis xyz="0 -0.9938588581379322 -0.11065518560268853"/>
		<child link="link_70"/>
		<parent link="link_0"/>
		<limit lower="0" upper="0.01"/>
	</joint>
	<link name="link_71">
		<visual name="key-72">
			<origin xyz="0.2305384505420256 -0.04784422458054394 0.11968905767549498"/>
			<geometry>
				<mesh filename="package://objects_description/keyboard/textured_objs/original-25.obj"/>
			</geometry>
		</visual>
		<collision>
			<origin xyz="0.2305384505420256 -0.04784422458054394 0.11968905767549498"/>
			<geometry>
				<mesh filename="package://objects_description/keyboard/textured_objs/original-25.obj"/>
			</geometry>
		</collision>
	</link>
	<joint name="joint_71" type="prismatic">
		<origin xyz="-0.2305384505420256 0.04784422458054394 -0.11968905767549498"/>
		<axis xyz="0 -0.9938588581379322 -0.11065518560268853"/>
		<child link="link_71"/>
		<parent link="link_0"/>
		<limit lower="0" upper="0.01"/>
	</joint>
	<link name="link_72">
		<visual name="key-73">
			<origin xyz="0.2305384505420256 -0.04784422458054394 0.11968905767549498"/>
			<geometry>
				<mesh filename="package://objects_description/keyboard/textured_objs/original-31.obj"/>
			</geometry>
		</visual>
		<collision>
			<origin xyz="0.2305384505420256 -0.04784422458054394 0.11968905767549498"/>
			<geometry>
				<mesh filename="package://objects_description/keyboard/textured_objs/original-31.obj"/>
			</geometry>
		</collision>
	</link>
	<joint name="joint_72" type="prismatic">
		<origin xyz="-0.2305384505420256 0.04784422458054394 -0.11968905767549498"/>
		<axis xyz="0 -0.9938588581379322 -0.11065518560268853"/>
		<child link="link_72"/>
		<parent link="link_0"/>
		<limit lower="0" upper="0.01"/>
	</joint>
	<link name="link_73">
		<visual name="key-74">
			<origin xyz="0.2305384505420256 -0.04784422458054394 0.11968905767549498"/>
			<geometry>
				<mesh filename="package://objects_description/keyboard/textured_objs/original-71.obj"/>
			</geometry>
		</visual>
		<collision>
			<origin xyz="0.2305384505420256 -0.04784422458054394 0.11968905767549498"/>
			<geometry>
				<mesh filename="package://objects_description/keyboard/textured_objs/original-71.obj"/>
			</geometry>
		</collision>
	</link>
	<joint name="joint_73" type="prismatic">
		<origin xyz="-0.2305384505420256 0.04784422458054394 -0.11968905767549498"/>
		<axis xyz="0 -0.9938588581379322 -0.11065518560268853"/>
		<child link="link_73"/>
		<parent link="link_0"/>
		<limit lower="0" upper="0.01"/>
	</joint>
	<link name="link_74">
		<visual name="key-75">
			<origin xyz="0.2305384505420256 -0.04784422458054394 0.11968905767549498"/>
			<geometry>
				<mesh filename="package://objects_description/keyboard/textured_objs/original-60.obj"/>
			</geometry>
		</visual>
		<collision>
			<origin xyz="0.2305384505420256 -0.04784422458054394 0.11968905767549498"/>
			<geometry>
				<mesh filename="package://objects_description/keyboard/textured_objs/original-60.obj"/>
			</geometry>
		</collision>
	</link>
	<joint name="joint_74" type="prismatic">
		<origin xyz="-0.2305384505420256 0.04784422458054394 -0.11968905767549498"/>
		<axis xyz="0 -0.9938588581379322 -0.11065518560268853"/>
		<child link="link_74"/>
		<parent link="link_0"/>
		<limit lower="0" upper="0.01"/>
	</joint>
	<link name="link_75">
		<visual name="key-76">
			<origin xyz="0.2305384505420256 -0.04784422458054394 0.11968905767549498"/>
			<geometry>
				<mesh filename="package://objects_description/keyboard/textured_objs/original-18.obj"/>
			</geometry>
		</visual>
		<collision>
			<origin xyz="0.2305384505420256 -0.04784422458054394 0.11968905767549498"/>
			<geometry>
				<mesh filename="package://objects_description/keyboard/textured_objs/original-18.obj"/>
			</geometry>
		</collision>
	</link>
	<joint name="joint_75" type="prismatic">
		<origin xyz="-0.2305384505420256 0.04784422458054394 -0.11968905767549498"/>
		<axis xyz="0 -0.9938588581379322 -0.11065518560268853"/>
		<child link="link_75"/>
		<parent link="link_0"/>
		<limit lower="0" upper="0.01"/>
	</joint>
	<link name="link_76">
		<visual name="key-77">
			<origin xyz="0.2305384505420256 -0.04784422458054394 0.11968905767549498"/>
			<geometry>
				<mesh filename="package://objects_description/keyboard/textured_objs/original-15.obj"/>
			</geometry>
		</visual>
		<collision>
			<origin xyz="0.2305384505420256 -0.04784422458054394 0.11968905767549498"/>
			<geometry>
				<mesh filename="package://objects_description/keyboard/textured_objs/original-15.obj"/>
			</geometry>
		</collision>
	</link>
	<joint name="joint_76" type="prismatic">
		<origin xyz="-0.2305384505420256 0.04784422458054394 -0.11968905767549498"/>
		<axis xyz="0 -0.9938588581379322 -0.11065518560268853"/>
		<child link="link_76"/>
		<parent link="link_0"/>
		<limit lower="0" upper="0.01"/>
	</joint>
	<link name="link_77">
		<visual name="key-78">
			<origin xyz="0.2305384505420256 -0.04784422458054394 0.11968905767549498"/>
			<geometry>
				<mesh filename="package://objects_description/keyboard/textured_objs/original-11.obj"/>
			</geometry>
		</visual>
		<collision>
			<origin xyz="0.2305384505420256 -0.04784422458054394 0.11968905767549498"/>
			<geometry>
				<mesh filename="package://objects_description/keyboard/textured_objs/original-11.obj"/>
			</geometry>
		</collision>
	</link>
	<joint name="joint_77" type="prismatic">
		<origin xyz="-0.2305384505420256 0.04784422458054394 -0.11968905767549498"/>
		<axis xyz="0 -0.9938588581379322 -0.11065518560268853"/>
		<child link="link_77"/>
		<parent link="link_0"/>
		<limit lower="0" upper="0.01"/>
	</joint>
</robot>
