<?xml version="1.0" ?>
<robot name="partnet_98bc840471b4fd568e6da51641e48238">
	<link name="base"/>
	<link name="link_0">
		<visual name="cabinet_door_surface-23">
			<origin xyz="0.6859974905547332 0.408064 -0.23868986657073282"/>
			<geometry>
				<mesh filename="package://objects_description/table/textured_objs/original-48.obj"/>
			</geometry>
		</visual>
		<visual name="handle-24">
			<origin xyz="0.6859974905547332 0.408064 -0.23868986657073282"/>
			<geometry>
				<mesh filename="package://objects_description/table/textured_objs/original-49.obj"/>
			</geometry>
		</visual>
		<visual name="glass-25">
			<origin xyz="0.6859974905547332 0.408064 -0.23868986657073282"/>
			<geometry>
				<mesh filename="package://objects_description/table/textured_objs/original-47.obj"/>
			</geometry>
		</visual>
		<collision>
			<origin xyz="0.6859974905547332 0.408064 -0.23868986657073282"/>
			<geometry>
				<mesh filename="package://objects_description/table/textured_objs/original-48.obj"/>
			</geometry>
		</collision>
		<collision>
			<origin xyz="0.6859974905547332 0.408064 -0.23868986657073282"/>
			<geometry>
				<mesh filename="package://objects_description/table/textured_objs/original-49.obj"/>
			</geometry>
		</collision>
		<collision>
			<origin xyz="0.6859974905547332 0.408064 -0.23868986657073282"/>
			<geometry>
				<mesh filename="package://objects_description/table/textured_objs/original-47.obj"/>
			</geometry>
		</collision>
	</link>
	<joint name="joint_0" type="revolute">
		<origin xyz="-0.6859974905547332 -0.408064 0.23868986657073282"/>
		<axis xyz="0 -1 0"/>
		<child link="link_0"/>
		<parent link="link_2"/>
		<limit lower="-0.0" upper="1.5707963267948966"/>
	</joint>
	<link name="link_1">
		<visual name="cabinet_door_surface-20">
			<origin xyz="-0.7087116182003554 0.37925599999999937 -0.23642974824319862"/>
			<geometry>
				<mesh filename="package://objects_description/table/textured_objs/original-53.obj"/>
			</geometry>
		</visual>
		<visual name="handle-21">
			<origin xyz="-0.7087116182003554 0.37925599999999937 -0.23642974824319862"/>
			<geometry>
				<mesh filename="package://objects_description/table/textured_objs/original-54.obj"/>
			</geometry>
		</visual>
		<visual name="glass-22">
			<origin xyz="-0.7087116182003554 0.37925599999999937 -0.23642974824319862"/>
			<geometry>
				<mesh filename="package://objects_description/table/textured_objs/original-52.obj"/>
			</geometry>
		</visual>
		<collision>
			<origin xyz="-0.7087116182003554 0.37925599999999937 -0.23642974824319862"/>
			<geometry>
				<mesh filename="package://objects_description/table/textured_objs/original-53.obj"/>
			</geometry>
		</collision>
		<collision>
			<origin xyz="-0.7087116182003554 0.37925599999999937 -0.23642974824319862"/>
			<geometry>
				<mesh filename="package://objects_description/table/textured_objs/original-54.obj"/>
			</geometry>
		</collision>
		<collision>
			<origin xyz="-0.7087116182003554 0.37925599999999937 -0.23642974824319862"/>
			<geometry>
				<mesh filename="package://objects_description/table/textured_objs/original-52.obj"/>
			</geometry>
		</collision>
	</link>
	<joint name="joint_1" type="revolute">
		<origin xyz="0.7087116182003554 -0.37925599999999937 0.23642974824319862"/>
		<axis xyz="0 1 0"/>
		<child link="link_1"/>
		<parent link="link_2"/>
		<limit lower="-0.6471680866394971" upper="0.91106186954104"/>
	</joint>
	<link name="link_2">
		<visual name="board-27">
			<origin xyz="0 0 0"/>
			<geometry>
				<mesh filename="package://objects_description/table/textured_objs/original-17.obj"/>
			</geometry>
		</visual>
		<visual name="board-27">
			<origin xyz="0 0 0"/>
			<geometry>
				<mesh filename="package://objects_description/table/textured_objs/original-4.obj"/>
			</geometry>
		</visual>
		<visual name="bar-29">
			<origin xyz="0 0 0"/>
			<geometry>
				<mesh filename="package://objects_description/table/textured_objs/original-5.obj"/>
			</geometry>
		</visual>
		<visual name="bar-30">
			<origin xyz="0 0 0"/>
			<geometry>
				<mesh filename="package://objects_description/table/textured_objs/original-14.obj"/>
			</geometry>
		</visual>
		<visual name="bar-31">
			<origin xyz="0 0 0"/>
			<geometry>
				<mesh filename="package://objects_description/table/textured_objs/original-13.obj"/>
			</geometry>
		</visual>
		<visual name="shelf-6">
			<origin xyz="0 0 0"/>
			<geometry>
				<mesh filename="package://objects_description/table/textured_objs/original-42.obj"/>
			</geometry>
		</visual>
		<visual name="shelf-7">
			<origin xyz="0 0 0"/>
			<geometry>
				<mesh filename="package://objects_description/table/textured_objs/original-41.obj"/>
			</geometry>
		</visual>
		<visual name="vertical_side_panel-8">
			<origin xyz="0 0 0"/>
			<geometry>
				<mesh filename="package://objects_description/table/textured_objs/original-15.obj"/>
			</geometry>
		</visual>
		<visual name="vertical_side_panel-9">
			<origin xyz="0 0 0"/>
			<geometry>
				<mesh filename="package://objects_description/table/textured_objs/original-16.obj"/>
			</geometry>
		</visual>
		<visual name="base_side_panel-10">
			<origin xyz="0 0 0"/>
			<geometry>
				<mesh filename="package://objects_description/table/textured_objs/original-7.obj"/>
			</geometry>
		</visual>
		<visual name="base_side_panel-10">
			<origin xyz="0 0 0"/>
			<geometry>
				<mesh filename="package://objects_description/table/textured_objs/original-3.obj"/>
			</geometry>
		</visual>
		<visual name="base_side_panel-11">
			<origin xyz="0 0 0"/>
			<geometry>
				<mesh filename="package://objects_description/table/textured_objs/original-1.obj"/>
			</geometry>
		</visual>
		<visual name="base_side_panel-11">
			<origin xyz="0 0 0"/>
			<geometry>
				<mesh filename="package://objects_description/table/textured_objs/original-18.obj"/>
			</geometry>
		</visual>
		<visual name="base_side_panel-11">
			<origin xyz="0 0 0"/>
			<geometry>
				<mesh filename="package://objects_description/table/textured_objs/original-6.obj"/>
			</geometry>
		</visual>
		<visual name="base_side_panel-12">
			<origin xyz="0 0 0"/>
			<geometry>
				<mesh filename="package://objects_description/table/textured_objs/original-8.obj"/>
			</geometry>
		</visual>
		<visual name="base_side_panel-12">
			<origin xyz="0 0 0"/>
			<geometry>
				<mesh filename="package://objects_description/table/textured_objs/original-2.obj"/>
			</geometry>
		</visual>
		<visual name="base_side_panel-13">
			<origin xyz="0 0 0"/>
			<geometry>
				<mesh filename="package://objects_description/table/textured_objs/original-12.obj"/>
			</geometry>
		</visual>
		<visual name="bottom_panel-14">
			<origin xyz="0 0 0"/>
			<geometry>
				<mesh filename="package://objects_description/table/textured_objs/original-20.obj"/>
			</geometry>
		</visual>
		<visual name="tabletop_connector-15">
			<origin xyz="0 0 0"/>
			<geometry>
				<mesh filename="package://objects_description/table/textured_objs/original-19.obj"/>
			</geometry>
		</visual>
		<visual name="tabletop_connector-16">
			<origin xyz="0 0 0"/>
			<geometry>
				<mesh filename="package://objects_description/table/textured_objs/original-28.obj"/>
			</geometry>
		</visual>
		<visual name="tabletop_connector-17">
			<origin xyz="0 0 0"/>
			<geometry>
				<mesh filename="package://objects_description/table/textured_objs/original-22.obj"/>
			</geometry>
		</visual>
		<visual name="bar_stretcher-32">
			<origin xyz="0 0 0"/>
			<geometry>
				<mesh filename="package://objects_description/table/textured_objs/original-55.obj"/>
			</geometry>
		</visual>
		<visual name="bar_stretcher-33">
			<origin xyz="0 0 0"/>
			<geometry>
				<mesh filename="package://objects_description/table/textured_objs/original-10.obj"/>
			</geometry>
		</visual>
		<visual name="bar_stretcher-34">
			<origin xyz="0 0 0"/>
			<geometry>
				<mesh filename="package://objects_description/table/textured_objs/original-9.obj"/>
			</geometry>
		</visual>
		<visual name="bar_stretcher-35">
			<origin xyz="0 0 0"/>
			<geometry>
				<mesh filename="package://objects_description/table/textured_objs/original-44.obj"/>
			</geometry>
		</visual>
		<visual name="bar_stretcher-36">
			<origin xyz="0 0 0"/>
			<geometry>
				<mesh filename="package://objects_description/table/textured_objs/original-43.obj"/>
			</geometry>
		</visual>
		<visual name="bar_stretcher-37">
			<origin xyz="0 0 0"/>
			<geometry>
				<mesh filename="package://objects_description/table/textured_objs/original-11.obj"/>
			</geometry>
		</visual>
		<collision>
			<origin xyz="0 0 0"/>
			<geometry>
				<mesh filename="package://objects_description/table/textured_objs/original-17.obj"/>
			</geometry>
		</collision>
		<collision>
			<origin xyz="0 0 0"/>
			<geometry>
				<mesh filename="package://objects_description/table/textured_objs/original-4.obj"/>
			</geometry>
		</collision>
		<collision>
			<origin xyz="0 0 0"/>
			<geometry>
				<mesh filename="package://objects_description/table/textured_objs/original-5.obj"/>
			</geometry>
		</collision>
		<collision>
			<origin xyz="0 0 0"/>
			<geometry>
				<mesh filename="package://objects_description/table/textured_objs/original-14.obj"/>
			</geometry>
		</collision>
		<collision>
			<origin xyz="0 0 0"/>
			<geometry>
				<mesh filename="package://objects_description/table/textured_objs/original-13.obj"/>
			</geometry>
		</collision>
		<collision>
			<origin xyz="0 0 0"/>
			<geometry>
				<mesh filename="package://objects_description/table/textured_objs/original-42.obj"/>
			</geometry>
		</collision>
		<collision>
			<origin xyz="0 0 0"/>
			<geometry>
				<mesh filename="package://objects_description/table/textured_objs/original-41.obj"/>
			</geometry>
		</collision>
		<collision>
			<origin xyz="0 0 0"/>
			<geometry>
				<mesh filename="package://objects_description/table/textured_objs/original-15.obj"/>
			</geometry>
		</collision>
		<collision>
			<origin xyz="0 0 0"/>
			<geometry>
				<mesh filename="package://objects_description/table/textured_objs/original-16.obj"/>
			</geometry>
		</collision>
		<collision>
			<origin xyz="0 0 0"/>
			<geometry>
				<mesh filename="package://objects_description/table/textured_objs/original-7.obj"/>
			</geometry>
		</collision>
		<collision>
			<origin xyz="0 0 0"/>
			<geometry>
				<mesh filename="package://objects_description/table/textured_objs/original-3.obj"/>
			</geometry>
		</collision>
		<collision>
			<origin xyz="0 0 0"/>
			<geometry>
				<mesh filename="package://objects_description/table/textured_objs/original-1.obj"/>
			</geometry>
		</collision>
		<collision>
			<origin xyz="0 0 0"/>
			<geometry>
				<mesh filename="package://objects_description/table/textured_objs/original-18.obj"/>
			</geometry>
		</collision>
		<collision>
			<origin xyz="0 0 0"/>
			<geometry>
				<mesh filename="package://objects_description/table/textured_objs/original-6.obj"/>
			</geometry>
		</collision>
		<collision>
			<origin xyz="0 0 0"/>
			<geometry>
				<mesh filename="package://objects_description/table/textured_objs/original-8.obj"/>
			</geometry>
		</collision>
		<collision>
			<origin xyz="0 0 0"/>
			<geometry>
				<mesh filename="package://objects_description/table/textured_objs/original-2.obj"/>
			</geometry>
		</collision>
		<collision>
			<origin xyz="0 0 0"/>
			<geometry>
				<mesh filename="package://objects_description/table/textured_objs/original-12.obj"/>
			</geometry>
		</collision>
		<collision>
			<origin xyz="0 0 0"/>
			<geometry>
				<mesh filename="package://objects_description/table/textured_objs/original-20.obj"/>
			</geometry>
		</collision>
		<collision>
			<origin xyz="0 0 0"/>
			<geometry>
				<mesh filename="package://objects_description/table/textured_objs/original-19.obj"/>
			</geometry>
		</collision>
		<collision>
			<origin xyz="0 0 0"/>
			<geometry>
				<mesh filename="package://objects_description/table/textured_objs/original-28.obj"/>
			</geometry>
		</collision>
		<collision>
			<origin xyz="0 0 0"/>
			<geometry>
				<mesh filename="package://objects_description/table/textured_objs/original-22.obj"/>
			</geometry>
		</collision>
		<collision>
			<origin xyz="0 0 0"/>
			<geometry>
				<mesh filename="package://objects_description/table/textured_objs/original-55.obj"/>
			</geometry>
		</collision>
		<collision>
			<origin xyz="0 0 0"/>
			<geometry>
				<mesh filename="package://objects_description/table/textured_objs/original-10.obj"/>
			</geometry>
		</collision>
		<collision>
			<origin xyz="0 0 0"/>
			<geometry>
				<mesh filename="package://objects_description/table/textured_objs/original-9.obj"/>
			</geometry>
		</collision>
		<collision>
			<origin xyz="0 0 0"/>
			<geometry>
				<mesh filename="package://objects_description/table/textured_objs/original-44.obj"/>
			</geometry>
		</collision>
		<collision>
			<origin xyz="0 0 0"/>
			<geometry>
				<mesh filename="package://objects_description/table/textured_objs/original-43.obj"/>
			</geometry>
		</collision>
		<collision>
			<origin xyz="0 0 0"/>
			<geometry>
				<mesh filename="package://objects_description/table/textured_objs/original-11.obj"/>
			</geometry>
		</collision>
	</link>
	<joint name="joint_2" type="fixed">
		<origin rpy="1.570796326794897 0 -1.570796326794897" xyz="0 0 0"/>
		<child link="link_2"/>
		<parent link="base"/>
	</joint>
</robot>
